Workbook
Name MatCategories: '2. Materials'!$B$16:$B$90
Name MatItems: '2. Materials'!$C$16:$C$90
Name SectionNames: '5. Pricing Sheet'!$C$17:$C$22

Sheet Read Me
B6: The Estimator
B7: by REMC
B8: Stop quoting on guesswork. Win the right jobs at the right price.
B11: How it works
B12: 1. Set Up | C12: On 'Your Setup', enter labour rates, mileage and your daily site costs ONCE. Everything pulls from here.
B13: 2. Materials | C13: Add your wholesaler prices on the 'Materials' tab. Edit prices when they move.
B14: 3. Travel & Stays | C14: If the job involves travel or staying away, use those tabs. Totals flow into the quote.
B15: 4. Pricing Sheet | C15: Build the job line-by-line. The live dashboard shows you what you're making.
B16: 5. Exclusions | C16: Tick what isn't included. They appear on the Client Quote automatically.
B17: 6. Send | C17: Save just the 'Client Quote' tab as a PDF (full instructions on that tab). Use 'Cheat Sheet' before every send.
B19: IMPORTANT — USE THIS AS A TEMPLATE
B20: This workbook is your master template. Keep it clean. For every new job, make a copy.
B21: Step 1 — Save the master safely | C21: Save this file once with a clear name like "The Estimator — MASTER.xlsx". Don't ever touch this version again to quote a job.
B22: Step 2 — For every new job, Save As | C22: Open the master. The first thing you do is File → Save As. Give the new file a name like "Quote — [Project Ref] — [Client Name].xlsx". Save it in a Quotes folder. Now you're working on a copy, not the master.
B23: Step 3 — Quote the job | C23: Add the project reference (from your enquiry register) into the Job Details on the Pricing Sheet. Build the quote. Print the Client Quote to PDF and send.
B24: Step 4 — Update the master, not your quotes | C24: When your supplier prices change, your labour rate changes, or you add new materials — update the MASTER file. Old quotes stay locked at the price they were quoted at.
B25: Why? If you quote on the master and save, your next quote starts with the last job's data in it. Mistakes happen that way.
B27: Cell colours
C28: Blue panels | D28: Inputs — type here
C29: White cells | D29: Calculated — don't overtype
C30: Yellow | D30: Key assumptions to double-check
B32: A reminder of these colours appears in the top-right of every working tab.
B34: Built by REMC Ltd — outsourced estimating for electrical contractors

Sheet 1. Your Setup
B2: Your Setup | G2: KEY
B3: Enter these once. The whole workbook uses them. | H3: Type here
H4: Calculated
H5: Check this
B7: YOUR BUSINESS | E7: YOUR LABOUR RATE
B8: Business name | C8: Your Business Ltd | E8: What you charge per hour for your time on site. This pre-fills every labour line on the Pricing Sheet — you can override it per line if a job needs a different rate.
B9: Address line 1 | C9: 1 Example Street | E9: Your hourly rate (£/hour) | F9: 45
B10: Address line 2 | C10: Town
B11: Postcode | C11: SW1 1AA | E11: MARGIN & OVERHEAD
B12: Phone | C12: 07123 456 789 | E12: Overhead recovery % | F12: 0.1
B13: Email | C13: you@yourbusiness.co.uk | E13: Target net margin % | F13: 0.2
B14: VAT number (blank if none) | E14: Default contingency % | F14: 0.05
B15: UTR / Company no. | E15: Default materials markup % | F15: 0.2
B16: Payment terms | C16: Payment due within 14 days of invoice | E16: Default subcontractor markup % | F16: 0.15
B17: Quote validity (days) | C17: 30
E18: ACCOMMODATION DEFAULTS
B19: TRAVEL & WORKING DAY | E19: £ per night (B&B / hotel) | F19: 75
B20: Mileage rate (£/mile) | C20: 0.45 | E20: Food allowance per day | F20: 25
B21: Average mph for travel time | C21: 35 | E21: Evening parking per night | F21: 0
B22: Working hours per day | C22: 8
B24: YOUR DAILY SITE COSTS
B25: What it costs you to be on site for one day, before labour or materials.
B26: Van (fuel, insurance, tax per day) | C26: 25
B27: Tools, consumables, PPE | C27: 11
B28: Welfare (food, drink, basics) | C28: 5
B29: Total daily site cost | C29: =SUM(C26:C28) -> 41
B31: Tip: hover over any label with a small red triangle for an explanation.

Sheet 2. Materials
B2: Materials Library | I2: KEY
B3: Your reusable price list. The Pricing Sheet pulls from here. | J3: Type here
J4: Calculated
J5: Check this
B6: HOW TO USE THIS TAB
B7: 1. Add every material you use regularly. The samples below are just to get you started — overwrite them, delete them, add to them.
B8: 2. Enter YOUR supplier's trade prices in the 'Trade price' column. Different sparkies have different deals — use yours, not the defaults.
B9: 3. Set YOUR markup % in the 'Markup %' column. The 'Sell price' calculates automatically.
B10: 4. Update prices MONTHLY (or whenever your supplier moves them). The 'Last updated' cell tracks when you last touched each line.
B11: 5. The Pricing Sheet pulls from this list. If a price is wrong here, every quote you write will be wrong too.
B13: LAST REVIEWED | C13: =TODAY() -> 46156 | D13: DAYS SINCE | E13: =TODAY()-C13 -> 0 | F13: STATUS | G13: =IF(C13="","Set date",IF(TODAY()-C13<=30,"✓ Up to date",IF(TODAY()-C13<=60,"⚠ Review soon","✗ OVERDUE — review now"))) -> ✓ Up to date
B15: Category | C15: Item description | D15: Unit | E15: Trade price | F15: Markup % | G15: Sell price | H15: Last updated
B16: Cable | C16: 1.0mm² T&E twin & earth | D16: m | E16: 0.65 | F16: 0.2 | G16: =E16*(1+F16) -> 0.78 | H16: 2026-04-01
B17: Cable | C17: 1.5mm² T&E twin & earth | D17: m | E17: 0.85 | F17: 0.2 | G17: =E17*(1+F17) -> 1.02 | H17: 2026-04-01
B18: Cable | C18: 2.5mm² T&E twin & earth | D18: m | E18: 1.2 | F18: 0.2 | G18: =E18*(1+F18) -> 1.44 | H18: 2026-04-01
B19: Cable | C19: 4.0mm² T&E twin & earth | D19: m | E19: 2.1 | F19: 0.2 | G19: =E19*(1+F19) -> 2.52 | H19: 2026-04-01
B20: Cable | C20: 6.0mm² T&E twin & earth | D20: m | E20: 3.4 | F20: 0.2 | G20: =E20*(1+F20) -> 4.08 | H20: 2026-04-01
B21: Cable | C21: 10.0mm² T&E twin & earth | D21: m | E21: 5.5 | F21: 0.2 | G21: =E21*(1+F21) -> 6.6 | H21: 2026-04-01
B22: Cable | C22: 1.5mm² 3-core SWA | D22: m | E22: 3.2 | F22: 0.2 | G22: =E22*(1+F22) -> 3.84 | H22: 2026-04-01
B23: Cable | C23: 2.5mm² 3-core SWA | D23: m | E23: 4.5 | F23: 0.2 | G23: =E23*(1+F23) -> 5.4 | H23: 2026-04-01
B24: Cable | C24: 1.5mm² 3-core flex (HO5VV-F) | D24: m | E24: 1.4 | F24: 0.2 | G24: =E24*(1+F24) -> 1.68 | H24: 2026-04-01
B25: Cable | C25: FP200 fire-rated 1.5mm² 2c+e | D25: m | E25: 2.2 | F25: 0.2 | G25: =E25*(1+F25) -> 2.64 | H25: 2026-04-01
B26: Accessories | C26: 13A single socket — white moulded | D26: ea | E26: 2.2 | F26: 0.25 | G26: =E26*(1+F26) -> 2.75 | H26: 2026-04-01
B27: Accessories | C27: 13A twin socket — white moulded | D27: ea | E27: 3.4 | F27: 0.25 | G27: =E27*(1+F27) -> 4.25 | H27: 2026-04-01
... B70: Data & Comms | C70: 24-port Cat6 patch panel | D70: ea | E70: 65 | F70: 0.2 | G70: =E70*(1+F70) -> 78 | H70: 2026-04-01
G71: =IFERROR(E71*(1+F71),0) -> 0
G72: =IFERROR(E72*(1+F72),0) -> 0
G73: =IFERROR(E73*(1+F73),0) -> 0
G74: =IFERROR(E74*(1+F74),0) -> 0
G75: =IFERROR(E75*(1+F75),0) -> 0
G76: =IFERROR(E76*(1+F76),0) -> 0
G77: =IFERROR(E77*(1+F77),0) -> 0
G78: =IFERROR(E78*(1+F78),0) -> 0
G79: =IFERROR(E79*(1+F79),0) -> 0
G80: =IFERROR(E80*(1+F80),0) -> 0
G81: =IFERROR(E81*(1+F81),0) -> 0
G82: =IFERROR(E82*(1+F82),0) -> 0
... G90: =IFERROR(E90*(1+F90),0) -> 0

Sheet 3. Travel
B2: Travel to Site | E2: KEY
B3: How much does getting to the job cost you? | F3: Type here
F4: Calculated
F5: Check this
B7: THE JOB
B8: Site postcode
B9: One-way miles to site | C9: 25
B10: Working days on this job | C10: =MAX(1,CEILING(IFERROR(SUM('5. Pricing Sheet'!J26:J47),0)/'1. Your Setup'!$C$22,1)) -> 1
B11: How many trips per day? | C11: 1
B12: Who's travelling? (1 if alone) | C12: 1
B13: Working days are auto-calculated. Type a number in the cell above to override.
B15: WHAT IT COSTS YOU
B16: Total miles for the job | C16: =C9*2*C11*C10 -> 50
B17: Mileage cost | C17: =C16*'1. Your Setup'!$C$20 -> 22.5
B18: Time spent driving (hours) | C18: =IFERROR(C16/'1. Your Setup'!$C$21*C12,0) -> 1.4285714
B19: Cost of that driving time | C19: =C18*'1. Your Setup'!$F$9 -> 64.285714
B21: TOTAL TRAVEL COST | C21: =C17+C19 -> 86.785714
B23: This total flows automatically into the Pricing Sheet.

Sheet 4. Accommodation
B2: Accommodation | E2: KEY
B3: Use this when the job needs staying away overnight. | F3: Type here
F4: Calculated
F5: Check this
B7: STAY DETAILS
B8: Nights away on this job | C8: 0
B9: How many people staying? | C9: 0
B10: £ per night per person | C10: ='1. Your Setup'!$F$19 -> 75
B11: Food allowance per person per day | C11: ='1. Your Setup'!$F$20 -> 25
B12: Evening parking per night | C12: ='1. Your Setup'!$F$21 -> 0
B13: Days on site (from Travel tab) | C13: ='3. Travel'!$C$10 -> 1
B15: WHAT IT COSTS YOU
B16: Accommodation cost | C16: =C8*C10*C9 -> 0
B17: Food cost | C17: =C13*C11*C9 -> 0
B18: Evening parking cost | C18: =C8*C12*C9 -> 0
B20: TOTAL ACCOMMODATION | C20: =SUM(C16:C18) -> 0
B22: This total flows automatically into the Pricing Sheet.

Sheet 5. Pricing Sheet
B2: Pricing Sheet | M2: KEY
B3: Group the work into sections (First fix, Second fix, etc.), then add line items. | N3: Type here
N4: Calculated
N5: Check this
B7: JOB DETAILS
B8: Project reference
B9: Client name
B10: Site address
B11: Quote date | E11: =TODAY() -> 46156
B12: Prepared by
B14: YOUR JOB SECTIONS — name the parts of work the client will see on the quote
B15: Examples: First fix, Second fix, Testing & Cert, Containment, EV charger install. Leave blank if you don't need that many.
B16: # | C16: Section name (this appears on the Client Quote)
B17: 1 | C17: First fix
B18: 2 | C18: Second fix
B19: 3 | C19: Testing & cert
B20: 4
B21: 5
B22: 6
B24: WORK ITEMS
B25: # | C25: Section | D25: Category | E25: Item description | F25: Unit | G25: Qty | H25: Mat £/u | I25: Mat total | J25: Lab hrs | K25: Lab £/hr | L25: Line total
B26: 1 | C26: First fix | D26: Distribution Equipment | E26: Consumer unit 12-way SPD | F26: =IFERROR(IF(E26="","",VLOOKUP(E26,'2. Materials'!$C$16:$H$90,2,FALSE())),"") -> ea | G26: 1 | H26: =IFERROR(IF(E26="","",VLOOKUP(E26,'2. Materials'!$C$16:$H$90,5,FALSE())),"") -> 166.75 | I26: =IFERROR(IF(OR(G26="",H26=""),0,G26*H26),0) -> 166.75 | J26: 2 | K26: ='1. Your Setup'!$F$9 -> 45 | L26: =IFERROR(I26+IFERROR(J26*K26,0),0) -> 256.75
B27: 2 | C27: First fix | D27: Distribution Equipment | E27: RCBO 6A type C | F27: =IFERROR(IF(E27="","",VLOOKUP(E27,'2. Materials'!$C$16:$H$90,2,FALSE())),"") -> ea | G27: 4 | H27: =IFERROR(IF(E27="","",VLOOKUP(E27,'2. Materials'!$C$16:$H$90,5,FALSE())),"") -> 21.6 | I27: =IFERROR(IF(OR(G27="",H27=""),0,G27*H27),0) -> 86.4 | J27: 0.2 | K27: ='1. Your Setup'!$F$9 -> 45 | L27: =IFERROR(I27+IFERROR(J27*K27,0),0) -> 95.4
B28: 3 | C28: First fix | D28: Distribution Equipment | E28: RCBO 16A type C | F28: =IFERROR(IF(E28="","",VLOOKUP(E28,'2. Materials'!$C$16:$H$90,2,FALSE())),"") -> ea | G28: 3 | H28: =IFERROR(IF(E28="","",VLOOKUP(E28,'2. Materials'!$C$16:$H$90,5,FALSE())),"") -> 21.6 | I28: =IFERROR(IF(OR(G28="",H28=""),0,G28*H28),0) -> 64.8 | J28: 0.2 | K28: ='1. Your Setup'!$F$9 -> 45 | L28: =IFERROR(I28+IFERROR(J28*K28,0),0) -> 73.8
B29: 4 | F29: =IFERROR(IF(E29="","",VLOOKUP(E29,'2. Materials'!$C$16:$H$90,2,FALSE())),"") | H29: =IFERROR(IF(E29="","",VLOOKUP(E29,'2. Materials'!$C$16:$H$90,5,FALSE())),"") | I29: =IFERROR(IF(OR(G29="",H29=""),0,G29*H29),0) -> 0 | K29: ='1. Your Setup'!$F$9 -> 45 | L29: =IFERROR(I29+IFERROR(J29*K29,0),0) -> 0
B30: 5 | C30: Testing & cert | D30: Testing & Cert | E30: EIC (new install) | F30: =IFERROR(IF(E30="","",VLOOKUP(E30,'2. Materials'!$C$16:$H$90,2,FALSE())),"") -> ea | G30: 1 | H30: =IFERROR(IF(E30="","",VLOOKUP(E30,'2. Materials'!$C$16:$H$90,5,FALSE())),"") -> 0 | I30: =IFERROR(IF(OR(G30="",H30=""),0,G30*H30),0) -> 0 | J30: 4 | K30: ='1. Your Setup'!$F$9 -> 45 | L30: =IFERROR(I30+IFERROR(J30*K30,0),0) -> 180
B31: 6 | F31: =IFERROR(IF(E31="","",VLOOKUP(E31,'2. Materials'!$C$16:$H$90,2,FALSE())),"") | H31: =IFERROR(IF(E31="","",VLOOKUP(E31,'2. Materials'!$C$16:$H$90,5,FALSE())),"") | I31: =IFERROR(IF(OR(G31="",H31=""),0,G31*H31),0) -> 0 | K31: ='1. Your Setup'!$F$9 -> 45 | L31: =IFERROR(I31+IFERROR(J31*K31,0),0) -> 0
B32: 7 | F32: =IFERROR(IF(E32="","",VLOOKUP(E32,'2. Materials'!$C$16:$H$90,2,FALSE())),"") | H32: =IFERROR(IF(E32="","",VLOOKUP(E32,'2. Materials'!$C$16:$H$90,5,FALSE())),"") | I32: =IFERROR(IF(OR(G32="",H32=""),0,G32*H32),0) -> 0 | K32: ='1. Your Setup'!$F$9 -> 45 | L32: =IFERROR(I32+IFERROR(J32*K32,0),0) -> 0
B33: 8 | F33: =IFERROR(IF(E33="","",VLOOKUP(E33,'2. Materials'!$C$16:$H$90,2,FALSE())),"") | H33: =IFERROR(IF(E33="","",VLOOKUP(E33,'2. Materials'!$C$16:$H$90,5,FALSE())),"") | I33: =IFERROR(IF(OR(G33="",H33=""),0,G33*H33),0) -> 0 | K33: ='1. Your Setup'!$F$9 -> 45 | L33: =IFERROR(I33+IFERROR(J33*K33,0),0) -> 0
B34: 9 | F34: =IFERROR(IF(E34="","",VLOOKUP(E34,'2. Materials'!$C$16:$H$90,2,FALSE())),"") | H34: =IFERROR(IF(E34="","",VLOOKUP(E34,'2. Materials'!$C$16:$H$90,5,FALSE())),"") | I34: =IFERROR(IF(OR(G34="",H34=""),0,G34*H34),0) -> 0 | K34: ='1. Your Setup'!$F$9 -> 45 | L34: =IFERROR(I34+IFERROR(J34*K34,0),0) -> 0
B35: 10 | F35: =IFERROR(IF(E35="","",VLOOKUP(E35,'2. Materials'!$C$16:$H$90,2,FALSE())),"") | H35: =IFERROR(IF(E35="","",VLOOKUP(E35,'2. Materials'!$C$16:$H$90,5,FALSE())),"") | I35: =IFERROR(IF(OR(G35="",H35=""),0,G35*H35),0) -> 0 | K35: ='1. Your Setup'!$F$9 -> 45 | L35: =IFERROR(I35+IFERROR(J35*K35,0),0) -> 0
B36: 11 | F36: =IFERROR(IF(E36="","",VLOOKUP(E36,'2. Materials'!$C$16:$H$90,2,FALSE())),"") | H36: =IFERROR(IF(E36="","",VLOOKUP(E36,'2. Materials'!$C$16:$H$90,5,FALSE())),"") | I36: =IFERROR(IF(OR(G36="",H36=""),0,G36*H36),0) -> 0 | K36: ='1. Your Setup'!$F$9 -> 45 | L36: =IFERROR(I36+IFERROR(J36*K36,0),0) -> 0
B37: 12 | F37: =IFERROR(IF(E37="","",VLOOKUP(E37,'2. Materials'!$C$16:$H$90,2,FALSE())),"") | H37: =IFERROR(IF(E37="","",VLOOKUP(E37,'2. Materials'!$C$16:$H$90,5,FALSE())),"") | I37: =IFERROR(IF(OR(G37="",H37=""),0,G37*H37),0) -> 0 | K37: ='1. Your Setup'!$F$9 -> 45 | L37: =IFERROR(I37+IFERROR(J37*K37,0),0) -> 0
B38: 13 | F38: =IFERROR(IF(E38="","",VLOOKUP(E38,'2. Materials'!$C$16:$H$90,2,FALSE())),"") | H38: =IFERROR(IF(E38="","",VLOOKUP(E38,'2. Materials'!$C$16:$H$90,5,FALSE())),"") | I38: =IFERROR(IF(OR(G38="",H38=""),0,G38*H38),0) -> 0 | K38: ='1. Your Setup'!$F$9 -> 45 | L38: =IFERROR(I38+IFERROR(J38*K38,0),0) -> 0
B39: 14 | F39: =IFERROR(IF(E39="","",VLOOKUP(E39,'2. Materials'!$C$16:$H$90,2,FALSE())),"") | H39: =IFERROR(IF(E39="","",VLOOKUP(E39,'2. Materials'!$C$16:$H$90,5,FALSE())),"") | I39: =IFERROR(IF(OR(G39="",H39=""),0,G39*H39),0) -> 0 | K39: ='1. Your Setup'!$F$9 -> 45 | L39: =IFERROR(I39+IFERROR(J39*K39,0),0) -> 0
B40: 15 | F40: =IFERROR(IF(E40="","",VLOOKUP(E40,'2. Materials'!$C$16:$H$90,2,FALSE())),"") | H40: =IFERROR(IF(E40="","",VLOOKUP(E40,'2. Materials'!$C$16:$H$90,5,FALSE())),"") | I40: =IFERROR(IF(OR(G40="",H40=""),0,G40*H40),0) -> 0 | K40: ='1. Your Setup'!$F$9 -> 45 | L40: =IFERROR(I40+IFERROR(J40*K40,0),0) -> 0
B41: 16 | F41: =IFERROR(IF(E41="","",VLOOKUP(E41,'2. Materials'!$C$16:$H$90,2,FALSE())),"") | H41: =IFERROR(IF(E41="","",VLOOKUP(E41,'2. Materials'!$C$16:$H$90,5,FALSE())),"") | I41: =IFERROR(IF(OR(G41="",H41=""),0,G41*H41),0) -> 0 | K41: ='1. Your Setup'!$F$9 -> 45 | L41: =IFERROR(I41+IFERROR(J41*K41,0),0) -> 0
B42: 17 | F42: =IFERROR(IF(E42="","",VLOOKUP(E42,'2. Materials'!$C$16:$H$90,2,FALSE())),"") | H42: =IFERROR(IF(E42="","",VLOOKUP(E42,'2. Materials'!$C$16:$H$90,5,FALSE())),"") | I42: =IFERROR(IF(OR(G42="",H42=""),0,G42*H42),0) -> 0 | K42: ='1. Your Setup'!$F$9 -> 45 | L42: =IFERROR(I42+IFERROR(J42*K42,0),0) -> 0
... B47: 22 | F47: =IFERROR(IF(E47="","",VLOOKUP(E47,'2. Materials'!$C$16:$H$90,2,FALSE())),"") | H47: =IFERROR(IF(E47="","",VLOOKUP(E47,'2. Materials'!$C$16:$H$90,5,FALSE())),"") | I47: =IFERROR(IF(OR(G47="",H47=""),0,G47*H47),0) -> 0 | K47: ='1. Your Setup'!$F$9 -> 45 | L47: =IFERROR(I47+IFERROR(J47*K47,0),0) -> 0
B48: Subtotal — work items | L48: =SUM(L26:L47) -> 605.95
...

Sheet 6. Exclusions
B2: Exclusions & Qualifications | E2: KEY
B3: Tick what is NOT in your price. Ticked items appear on the Client Quote. | F3: Type here
F4: Calculated
F5: Check this
B7: Tip: most jobs go wrong because of what wasn't excluded in writing.
B9: TICK TO EXCLUDE
C10: Builder's work — chasing, lifting and re-laying floor finishes
C11: Making good of plaster, paintwork or decoration
C12: Lifting and re-laying carpets, laminate, vinyl or tiled flooring
C13: Removal, alteration or refixing of fitted furniture
C14: Working at height above 2m (scaffold, MEWP or tower hire excluded)
C15: Asbestos survey, removal or encapsulation
C16: Temporary electrical supply or generator hire
C17: Temporary lighting for other trades
C18: Out-of-hours, weekend or bank holiday working
C19: Permits, licences or local authority fees
B20: Y | C20: Parking permits, suspensions or congestion charges
B21: Y | C21: Welfare facilities (assumed provided by main contractor or client)
B22: Y | C22: Skip hire or waste removal of non-electrical materials
B23: Y | C23: Disposal of fluorescent tubes or hazardous waste
B24: Y | C24: Statutory testing or commissioning beyond standard EICR
B25: Y | C25: Third-party witnessing, inspection or sign-off fees
B26: Y | C26: Builder's clean or final clean of working areas
C27: Programme acceleration or out-of-sequence working
C28: Standing time caused by other trades or delayed access
C29: Specialist commissioning (BMS, fire alarm cause-and-effect, etc.)
C30: Builders' attendance: power, lighting, hoisting, scaffolding
C31: Design, drawings, schematics or CAD work
C32: Builder's openings or holes through structural elements
C33: Fire stopping of penetrations through compartments
C34: Containment, brackets or fixings not specified in the scope
C35: Earthing or bonding beyond immediate scope
C36: Smart-home programming, app setup or user training
C37: Network configuration or commissioning of IT equipment
C38: Anything not expressly listed in the scope of works
B40: ADD YOUR OWN

Sheet 7. Check Sheet
B2: Pre-Send Check Sheet | E2: KEY
B3: 15 checks before every send. Run the list. | F3: Type here
F4: Calculated
F5: Check this
B7: CHECK BEFORE YOU SEND
B8: ☐ | C8: 1. Travel time included BOTH ways for every working day?
B9: ☐ | C9: 2. Enough labour hours, or have you been optimistic again?
B10: ☐ | C10: 3. Materials prices from this week, not last year?
B11: ☐ | C11: 4. Daily site costs (van, tools, welfare) per day included?
B12: ☐ | C12: 5. If staying away — accommodation AND food both in?
B13: ☐ | C13: 6. Overhead recovery added? (Or are you running the business for free?)
B14: ☐ | C14: 7. Margin where it needs to be — not where you hope?
B15: ☐ | C15: 8. Testing, certification and notification fees priced?
B16: ☐ | C16: 9. Subcontractor markup added?
B17: ☐ | C17: 10. Contingency for things that always go wrong?
B18: ☐ | C18: 11. Builder's work clearly excluded?
B19: ☐ | C19: 12. Working hours stated? (You're not on site at 7am at standard rate.)
... B22: ☐ | C22: 15. Re-read the scope — are you pricing what they actually asked for?
B24: A bad quote that wins is worse than a good quote that loses.

Sheet 8. Client Quote
B2: ='1. Your Setup'!$C$8 -> Your Business Ltd | H2: HOW TO SEND THIS TO YOUR CLIENT
B3: =IF('1. Your Setup'!$C$9="","",'1. Your Setup'!$C$9&", ")&IF('1. Your Setup'!$C$10="","",'1. Your Setup'!$C$10&", ")&IF('1. Your Setup'!$C$11="","",'1. Your Setup'!$C$11)&IF('1. Your Setup'!$C$12="",""," | "&'1. Your Setup'!$C$12)&IF('1. Your Setup'!$C$13="",""," | "&'1. Your Setup'!$C$13) -> 1 Example Street, Town, SW1 1AA | 07123 456 789 | you@yourbusiness.co.uk | H3: Save just this tab as a PDF — not the whole workbook.
H4: 1. | I4: Make sure you're on this tab.
H5: 2. | I5: File → Save As (or Export on Mac).
B6: QUOTATION | H6: 3. | I6: Name the file: 'Quote — [your ref].pdf'.
H7: 4. | I7: Set file type to PDF.
B8: To: | C8: =IF('5. Pricing Sheet'!$E$9="","",'5. Pricing Sheet'!$E$9) | E8: Quote ref: | F8: =IF('5. Pricing Sheet'!$E$8="","",'5. Pricing Sheet'!$E$8) | H8: 5. | I8: Click 'Options' or 'Show Details'.
B9: Site: | C9: =IF('5. Pricing Sheet'!$E$10="","",'5. Pricing Sheet'!$E$10) | E9: Date: | F9: ='5. Pricing Sheet'!$E$11 -> 46156 | H9: 6. | I9: Tick 'Active Sheet(s)' — not 'Workbook'.
B10: Prepared by: | C10: =IF('5. Pricing Sheet'!$E$12="","",'5. Pricing Sheet'!$E$12) | E10: Valid for: | F10: ='1. Your Setup'!$C$17&" days" -> 30 days | H10: 7. | I10: Save. Email the PDF to your client.
B12: PRICE SUMMARY | H12: ⚠ IMPORTANT
B13: =IF('5. Pricing Sheet'!$C$17="","",'5. Pricing Sheet'!$C$17) -> First fix | F13: =IF('5. Pricing Sheet'!$C$17="","",IFERROR(SUMIF('5. Pricing Sheet'!$C$26:$C$47,'5. Pricing Sheet'!$C$17,'5. Pricing Sheet'!$L$26:$L$47)/'5. Pricing Sheet'!$L$48*('5. Pricing Sheet'!$L$65-'5. Pricing Sheet'!$L$55-'5. Pricing Sheet'!$L$56-'5. Pricing Sheet'!$L$57),0)) -> 744.65222 | H13: If you save the whole workbook, your client
B14: =IF('5. Pricing Sheet'!$C$18="","",'5. Pricing Sheet'!$C$18) -> Second fix | F14: =IF('5. Pricing Sheet'!$C$18="","",IFERROR(SUMIF('5. Pricing Sheet'!$C$26:$C$47,'5. Pricing Sheet'!$C$18,'5. Pricing Sheet'!$L$26:$L$47)/'5. Pricing Sheet'!$L$48*('5. Pricing Sheet'!$L$65-'5. Pricing Sheet'!$L$55-'5. Pricing Sheet'!$L$56-'5. Pricing Sheet'!$L$57),0)) -> 0 | H14: sees your costs and margin. Only this tab.
B15: =IF('5. Pricing Sheet'!$C$19="","",'5. Pricing Sheet'!$C$19) -> Testing & cert | F15: =IF('5. Pricing Sheet'!$C$19="","",IFERROR(SUMIF('5. Pricing Sheet'!$C$26:$C$47,'5. Pricing Sheet'!$C$19,'5. Pricing Sheet'!$L$26:$L$47)/'5. Pricing Sheet'!$L$48*('5. Pricing Sheet'!$L$65-'5. Pricing Sheet'!$L$55-'5. Pricing Sheet'!$L$56-'5. Pricing Sheet'!$L$57),0)) -> 314.67872
B16: =IF('5. Pricing Sheet'!$C$20="","",'5. Pricing Sheet'!$C$20) | F16: =IF('5. Pricing Sheet'!$C$20="","",IFERROR(SUMIF('5. Pricing Sheet'!$C$26:$C$47,'5. Pricing Sheet'!$C$20,'5. Pricing Sheet'!$L$26:$L$47)/'5. Pricing Sheet'!$L$48*('5. Pricing Sheet'!$L$65-'5. Pricing Sheet'!$L$55-'5. Pricing Sheet'!$L$56-'5. Pricing Sheet'!$L$57),0)) | H16: 💡 TIP
B17: =IF('5. Pricing Sheet'!$C$21="","",'5. Pricing Sheet'!$C$21) | F17: =IF('5. Pricing Sheet'!$C$21="","",IFERROR(SUMIF('5. Pricing Sheet'!$C$26:$C$47,'5. Pricing Sheet'!$C$21,'5. Pricing Sheet'!$L$26:$L$47)/'5. Pricing Sheet'!$L$48*('5. Pricing Sheet'!$L$65-'5. Pricing Sheet'!$L$55-'5. Pricing Sheet'!$L$56-'5. Pricing Sheet'!$L$57),0)) | H17: Match the PDF filename to your project ref.
B18: =IF('5. Pricing Sheet'!$C$22="","",'5. Pricing Sheet'!$C$22) | F18: =IF('5. Pricing Sheet'!$C$22="","",IFERROR(SUMIF('5. Pricing Sheet'!$C$26:$C$47,'5. Pricing Sheet'!$C$22,'5. Pricing Sheet'!$L$26:$L$47)/'5. Pricing Sheet'!$L$48*('5. Pricing Sheet'!$L$65-'5. Pricing Sheet'!$L$55-'5. Pricing Sheet'!$L$56-'5. Pricing Sheet'!$L$57),0))
B19: =IF(IFERROR(SUMIF('5. Pricing Sheet'!$C$26:$C$47,"",'5. Pricing Sheet'!$L$26:$L$47)/'5. Pricing Sheet'!$L$48*('5. Pricing Sheet'!$L$65-'5. Pricing Sheet'!$L$55-'5. Pricing Sheet'!$L$56-'5. Pricing Sheet'!$L$57),0)=0,"","General works") | F19: =IFERROR(SUMIF('5. Pricing Sheet'!$C$26:$C$47,"",'5. Pricing Sheet'!$L$26:$L$47)/'5. Pricing Sheet'!$L$48*('5. Pricing Sheet'!$L$65-'5. Pricing Sheet'!$L$55-'5. Pricing Sheet'!$L$56-'5. Pricing Sheet'!$L$57),0) -> 0
B20: =IF(('5. Pricing Sheet'!$L$55+'5. Pricing Sheet'!$L$56)=0,"","Subcontracted works") | F20: ='5. Pricing Sheet'!$L$55+'5. Pricing Sheet'!$L$56 -> 0
B21: =IF('5. Pricing Sheet'!$L$57=0,"","Provisional sums / other") | F21: ='5. Pricing Sheet'!$L$57 -> 0
B22: NET QUOTE (excluding VAT) | F22: ='5. Pricing Sheet'!$L$65 -> 1059.3309
B23: VAT (if applicable) | F23: ='5. Pricing Sheet'!$L$66 -> 0
B24: TOTAL DUE | F24: ='5. Pricing Sheet'!$L$67 -> 1059.3309
B25: The above price includes all travel, site running costs, and management.
B27: EXCLUSIONS & QUALIFICATIONS
B28: This price specifically excludes:
B29: =IF(UPPER('6. Exclusions'!B10)="Y","• "&'6. Exclusions'!C10,"")
B30: =IF(UPPER('6. Exclusions'!B11)="Y","• "&'6. Exclusions'!C11,"")
B31: =IF(UPPER('6. Exclusions'!B12)="Y","• "&'6. Exclusions'!C12,"")
B32: =IF(UPPER('6. Exclusions'!B13)="Y","• "&'6. Exclusions'!C13,"")
B33: =IF(UPPER('6. Exclusions'!B14)="Y","• "&'6. Exclusions'!C14,"")
B34: =IF(UPPER('6. Exclusions'!B15)="Y","• "&'6. Exclusions'!C15,"")
B35: =IF(UPPER('6. Exclusions'!B16)="Y","• "&'6. Exclusions'!C16,"")
B36: =IF(UPPER('6. Exclusions'!B17)="Y","• "&'6. Exclusions'!C17,"")
B37: =IF(UPPER('6. Exclusions'!B18)="Y","• "&'6. Exclusions'!C18,"")
B38: =IF(UPPER('6. Exclusions'!B19)="Y","• "&'6. Exclusions'!C19,"")
B39: =IF(UPPER('6. Exclusions'!B20)="Y","• "&'6. Exclusions'!C20,"") -> • Parking permits, suspensions or congestion charges
B40: =IF(UPPER('6. Exclusions'!B21)="Y","• "&'6. Exclusions'!C21,"") -> • Welfare facilities (assumed provided by main contractor or client)
... B67: =IF(UPPER('6. Exclusions'!B48)="Y","• "&'6. Exclusions'!C48,"")
B69: TERMS
B70: ='1. Your Setup'!$C$16 -> Payment due within 14 days of invoice
...
